<?xml version="1.0" encoding="UTF-8"?>
<testng-results skipped="0" failed="1" total="2" passed="1">
  <reporter-output>
  </reporter-output>
  <suite name="Hackathon-Demo" duration-ms="51102" started-at="2018-10-25T09:46:52Z" finished-at="2018-10-25T09:47:43Z">
    <groups>
    </groups>
    <test name="Write new post" duration-ms="51102" started-at="2018-10-25T09:46:52Z" finished-at="2018-10-25T09:47:43Z">
      <class name="hackathon.demo.TestClass">
        <test-method status="PASS" signature="LoginSuccessTC()[pri:0, instance:hackathon.demo.TestClass@3e6fa38a]" name="LoginSuccessTC" duration-ms="32622" started-at="2018-10-25T15:17:06Z" description="Valid login scenerio with authenticate username &amp; password" finished-at="2018-10-25T15:17:39Z">
          <reporter-output>
          </reporter-output>
        </test-method> <!-- LoginSuccessTC -->
        <test-method status="FAIL" signature="LoginFailTC()[pri:0, instance:hackathon.demo.TestClass@3e6fa38a]" name="LoginFailTC" duration-ms="3207" started-at="2018-10-25T15:17:39Z" description="Invalid login scenerio with wrong username &amp; password" finished-at="2018-10-25T15:17:42Z">
          <exception class="java.lang.AssertionError">
            <message>
              <![CDATA[expected [Nielsen Studio] but found [Nielsen Studio » Log in]]]>
            </message>
            <full-stacktrace>
              <![CDATA[java.lang.AssertionError: expected [Nielsen Studio] but found [Nielsen Studio » Log in]
	at org.testng.Assert.fail(Assert.java:94)
	at org.testng.Assert.failNotEquals(Assert.java:494)
	at org.testng.Assert.assertEquals(Assert.java:123)
	at org.testng.Assert.assertEquals(Assert.java:176)
	at org.testng.Assert.assertEquals(Assert.java:186)
	at hackathon.demo.TestClass.LoginFailTC(TestClass.java:48)
	at sun.reflect.NativeMethodAccessorImpl.invoke0(Native Method)
	at sun.reflect.NativeMethodAccessorImpl.invoke(Unknown Source)
	at sun.reflect.DelegatingMethodAccessorImpl.invoke(Unknown Source)
	at java.lang.reflect.Method.invoke(Unknown Source)
	at org.testng.internal.MethodInvocationHelper.invokeMethod(MethodInvocationHelper.java:80)
	at org.testng.internal.Invoker.invokeMethod(Invoker.java:714)
	at org.testng.internal.Invoker.invokeTestMethod(Invoker.java:901)
	at org.testng.internal.Invoker.invokeTestMethods(Invoker.java:1231)
	at org.testng.internal.TestMethodWorker.invokeTestMethods(TestMethodWorker.java:127)
	at org.testng.internal.TestMethodWorker.run(TestMethodWorker.java:111)
	at org.testng.TestRunner.privateRun(TestRunner.java:767)
	at org.testng.TestRunner.run(TestRunner.java:617)
	at org.testng.SuiteRunner.runTest(SuiteRunner.java:334)
	at org.testng.SuiteRunner.runSequentially(SuiteRunner.java:329)
	at org.testng.SuiteRunner.privateRun(SuiteRunner.java:291)
	at org.testng.SuiteRunner.run(SuiteRunner.java:240)
	at org.testng.SuiteRunnerWorker.runSuite(SuiteRunnerWorker.java:52)
	at org.testng.SuiteRunnerWorker.run(SuiteRunnerWorker.java:86)
	at org.testng.TestNG.runSuitesSequentially(TestNG.java:1198)
	at org.testng.TestNG.runSuitesLocally(TestNG.java:1123)
	at org.testng.TestNG.run(TestNG.java:1031)
	at org.testng.remote.AbstractRemoteTestNG.run(AbstractRemoteTestNG.java:114)
	at org.testng.remote.RemoteTestNG.initAndRun(RemoteTestNG.java:251)
	at org.testng.remote.RemoteTestNG.main(RemoteTestNG.java:77)
]]>
            </full-stacktrace>
          </exception> <!-- java.lang.AssertionError -->
          <reporter-output>
          </reporter-output>
        </test-method> <!-- LoginFailTC -->
      </class> <!-- hackathon.demo.TestClass -->
    </test> <!-- Write new post -->
  </suite> <!-- Hackathon-Demo -->
</testng-results>
